Homepage was accessed at 2023-10-26 12:21:56.073440 hours!
Not Found: /favicon.ico
Homepage was accessed at 2023-10-28 15:00:51.751662 hours!
Internal Server Error: /post_info/send_code_for_varify_mobile_address
Traceback (most recent call last):
  File "C:\Python311\Lib\site-packages\django\core\handlers\exception.py", line 56, in inner
    response = get_response(request)
               ^^^^^^^^^^^^^^^^^^^^^
  File "C:\Python311\Lib\site-packages\django\core\handlers\base.py", line 197, in _get_response
    response = wrapped_callback(request, *callback_args, **callback_kwargs)
               ^^^^^^^^^^^^^^^^^^^^^^^^^^^^^^^^^^^^^^^^^^^^^^^^^^^^^^^^^^^^
  File "C:\Python311\Lib\site-packages\django\views\decorators\csrf.py", line 55, in wrapped_view
    return view_func(*args, **kwargs)
           ^^^^^^^^^^^^^^^^^^^^^^^^^^
  File "C:\Python311\Lib\site-packages\django\views\generic\base.py", line 103, in view
    return self.dispatch(request, *args, **kwargs)
           ^^^^^^^^^^^^^^^^^^^^^^^^^^^^^^^^^^^^^^^
  File "C:\Python311\Lib\site-packages\rest_framework\views.py", line 509, in dispatch
    response = self.handle_exception(exc)
               ^^^^^^^^^^^^^^^^^^^^^^^^^^
  File "C:\Python311\Lib\site-packages\rest_framework\views.py", line 469, in handle_exception
    self.raise_uncaught_exception(exc)
  File "C:\Python311\Lib\site-packages\rest_framework\views.py", line 480, in raise_uncaught_exception
    raise exc
  File "C:\Python311\Lib\site-packages\rest_framework\views.py", line 506, in dispatch
    response = handler(request, *args, **kwargs)
               ^^^^^^^^^^^^^^^^^^^^^^^^^^^^^^^^^
  File "G:\django1\spadelc\post_information\views.py", line 185, in post
    user.save()
    ^^^^^^^^^
AttributeError: 'QuerySet' object has no attribute 'save'
Internal Server Error: /post_info/send_code_for_varify_mobile_address
Traceback (most recent call last):
  File "C:\Python311\Lib\site-packages\django\core\handlers\exception.py", line 56, in inner
    response = get_response(request)
               ^^^^^^^^^^^^^^^^^^^^^
  File "C:\Python311\Lib\site-packages\django\core\handlers\base.py", line 197, in _get_response
    response = wrapped_callback(request, *callback_args, **callback_kwargs)
               ^^^^^^^^^^^^^^^^^^^^^^^^^^^^^^^^^^^^^^^^^^^^^^^^^^^^^^^^^^^^
  File "C:\Python311\Lib\site-packages\django\views\decorators\csrf.py", line 55, in wrapped_view
    return view_func(*args, **kwargs)
           ^^^^^^^^^^^^^^^^^^^^^^^^^^
  File "C:\Python311\Lib\site-packages\django\views\generic\base.py", line 103, in view
    return self.dispatch(request, *args, **kwargs)
           ^^^^^^^^^^^^^^^^^^^^^^^^^^^^^^^^^^^^^^^
  File "C:\Python311\Lib\site-packages\rest_framework\views.py", line 509, in dispatch
    response = self.handle_exception(exc)
               ^^^^^^^^^^^^^^^^^^^^^^^^^^
  File "C:\Python311\Lib\site-packages\rest_framework\views.py", line 469, in handle_exception
    self.raise_uncaught_exception(exc)
  File "C:\Python311\Lib\site-packages\rest_framework\views.py", line 480, in raise_uncaught_exception
    raise exc
  File "C:\Python311\Lib\site-packages\rest_framework\views.py", line 506, in dispatch
    response = handler(request, *args, **kwargs)
               ^^^^^^^^^^^^^^^^^^^^^^^^^^^^^^^^^
  File "G:\django1\spadelc\post_information\views.py", line 186, in post
    user.save()
    ^^^^^^^^^
AttributeError: 'QuerySet' object has no attribute 'save'
Internal Server Error: /post_info/send_code_for_varify_mobile_address
Traceback (most recent call last):
  File "C:\Python311\Lib\site-packages\django\core\handlers\exception.py", line 56, in inner
    response = get_response(request)
               ^^^^^^^^^^^^^^^^^^^^^
  File "C:\Python311\Lib\site-packages\django\core\handlers\base.py", line 197, in _get_response
    response = wrapped_callback(request, *callback_args, **callback_kwargs)
               ^^^^^^^^^^^^^^^^^^^^^^^^^^^^^^^^^^^^^^^^^^^^^^^^^^^^^^^^^^^^
  File "C:\Python311\Lib\site-packages\django\views\decorators\csrf.py", line 55, in wrapped_view
    return view_func(*args, **kwargs)
           ^^^^^^^^^^^^^^^^^^^^^^^^^^
  File "C:\Python311\Lib\site-packages\django\views\generic\base.py", line 103, in view
    return self.dispatch(request, *args, **kwargs)
           ^^^^^^^^^^^^^^^^^^^^^^^^^^^^^^^^^^^^^^^
  File "C:\Python311\Lib\site-packages\rest_framework\views.py", line 509, in dispatch
    response = self.handle_exception(exc)
               ^^^^^^^^^^^^^^^^^^^^^^^^^^
  File "C:\Python311\Lib\site-packages\rest_framework\views.py", line 469, in handle_exception
    self.raise_uncaught_exception(exc)
  File "C:\Python311\Lib\site-packages\rest_framework\views.py", line 480, in raise_uncaught_exception
    raise exc
  File "C:\Python311\Lib\site-packages\rest_framework\views.py", line 506, in dispatch
    response = handler(request, *args, **kwargs)
               ^^^^^^^^^^^^^^^^^^^^^^^^^^^^^^^^^
  File "G:\django1\spadelc\post_information\views.py", line 186, in post
    user.save()
    ^^^^^^^^^
AttributeError: 'QuerySet' object has no attribute 'save'
Not Found: /favicon.ico
